<?xml version="1.0" encoding="utf-8" ?>
<!-- This URDF was automatically created by SolidWorks to URDF Exporter! Originally created by Stephen Brawner (brawner@gmail.com) 
     Commit Version: 1.6.0-4-g7f85cfe  Build Version: 1.6.7995.38578
     For more information, please see http://wiki.ros.org/sw_urdf_exporter -->
<robot name="robotino_arm_v2_udf">
    <link name="base_link">
        
<inertial>
            <origin xyz="-0.0370127633091683 0.019070320751848 0.144702744937737" rpy="0 0 0" />
            <mass value="0.0485300603816627" />
            <inertia ixx="1.21348391060661E-05" ixy="-1.83170561820002E-07" ixz="2.01283221627451E-09" iyy="1.03176250980936E-05" iyz="8.98306870809956E-08" izz="1.3705089569295E-05" />
        </inertial>

        <visual>
            <origin xyz="0 0 0" rpy="0 0 0" />
            <geometry>
                <mesh filename="package://robotino_arm_v2_udf/meshes/base_link.STL" />
            </geometry>
            <material name="">
                <color rgba="0.792156862745098 0.819607843137255 0.933333333333333 1" />
            </material>
        </visual>
        <collision>
            <origin xyz="0 0 0" rpy="0 0 0" />
            <geometry>
                <mesh filename="package://robotino_arm_v2_udf/meshes/base_link.STL" />
            </geometry>
        </collision>
    </link>
    <link name="world" />
    <joint name="fix" type="fixed">
        <parent link="world" />
        <child link="base_link" />
        <origin xyz="0.0 0.0 0.5" rpy="1.57 3.14 0.0" />
    </joint>
    <link name="L1">
        
<inertial>
            <origin xyz="0.0218613397170321 -0.0643083979647138 -0.0106559317352375" rpy="0 0 0" />
            <mass value="0.0123298942666567" />
            <inertia ixx="1.86723406131852E-05" ixy="-3.47242222560863E-10" ixz="1.18024925877695E-09" iyy="6.09881410181813E-06" iyz="-8.12828881398934E-07" izz="2.15012069724987E-05" />
        </inertial>

        <visual>
            <origin xyz="0 0 0" rpy="0 0 0" />
            <geometry>
                <mesh filename="package://robotino_arm_v2_udf/meshes/L1.STL" />
            </geometry>
            <material name="">
                <color rgba="0.792156862745098 0.819607843137255 0.933333333333333 1" />
            </material>
        </visual>
        <collision>
            <origin xyz="0 0 0" rpy="0 0 0" />
            <geometry>
                <mesh filename="package://robotino_arm_v2_udf/meshes/L1.STL" />
            </geometry>
        </collision>
    </link>
    <joint name="J1" type="revolute">
        <origin xyz="-0.015177 -0.14501 0.0031767" rpy="1.5325 -1.6571E-05 3.1412" />
        <parent link="base_link" />
        <child link="L1" />
        <axis xyz="1 0 -0.00043232" />
        <limit lower="0" upper="1.8" effort="10" velocity="0.2" />
    </joint>
    <link name="L2">
        
<inertial>
            <origin xyz="0.0218828627980577 0.002734641651011 0.0384853882508786" rpy="0 0 0" />
            <mass value="0.0879186008437833" />
            <inertia ixx="2.08913128379421E-05" ixy="2.66064625040772E-08" ixz="3.62172435526932E-07" iyy="2.46188638028951E-05" iyz="-6.75708643034757E-07" izz="1.5509544710887E-05" />
        </inertial>

        <visual>
            <origin xyz="0 0 0" rpy="0 0 0" />
            <geometry>
                <mesh filename="package://robotino_arm_v2_udf/meshes/L2.STL" />
            </geometry>
            <material name="">
                <color rgba="0.792156862745098 0.819607843137255 0.933333333333333 1" />
            </material>
        </visual>
        <collision>
            <origin xyz="0 0 0" rpy="0 0 0" />
            <geometry>
                <mesh filename="package://robotino_arm_v2_udf/meshes/L2.STL" />
            </geometry>
        </collision>
    </link>
    <joint name="J2" type="revolute">
        <origin xyz="0 -0.13842 -0.0076949" rpy="1.7 0.00048802 -0.00042872" />
        <parent link="L1" />
        <child link="L2" />
        <axis xyz="1 0 -0.00043232" />
        <limit lower="-1.8" upper="1.8" effort="10" velocity="0.2" />
    </joint>
    <link name="L3">
        
<inertial>
            <origin xyz="0.0210324963278343 0.00345434614035189 0.0443927660933133" rpy="0 0 0" />
            <mass value="0.0470068003445836" />
            <inertia ixx="8.27072638092313E-06" ixy="1.82174461954528E-07" ixz="-1.31004150631563E-08" iyy="1.15598328470863E-05" iyz="1.42985163489217E-07" izz="1.33891638883011E-05" />
        </inertial>

        <visual>
            <origin xyz="0 0 0" rpy="0 0 0" />
            <geometry>
                <mesh filename="package://robotino_arm_v2_udf/meshes/L3.STL" />
            </geometry>
            <material name="">
                <color rgba="0.792156862745098 0.819607843137255 0.933333333333333 1" />
            </material>
        </visual>
        <collision>
            <origin xyz="0 0 0" rpy="0 0 0" />
            <geometry>
                <mesh filename="package://robotino_arm_v2_udf/meshes/L3.STL" />
            </geometry>
        </collision>
    </link>
    <joint name="J3" type="revolute">
        <origin xyz="3.3285E-05 0.0056816 0.076991" rpy="0.0042565 0 0" />
        <parent link="L2" />
        <child link="L3" />
        <axis xyz="1 0 -0.00043232" />
        <limit lower="-1.8" upper="1.8" effort="10" velocity="0.2" />
    </joint>
    <link name="GR">
        
<inertial>
            <origin xyz="-0.00443543982926508 -4.33266183444692E-05 -0.0353860660374369" rpy="0 0 0" />
            <mass value="0.0182294853598354" />
            <inertia ixx="1.0394691303712E-05" ixy="4.83375753942016E-10" ixz="9.97321914417416E-08" iyy="6.1120326767523E-06" iyz="7.72174800352589E-10" izz="5.70322869333795E-06" />
        </inertial>

        <visual>
            <origin xyz="0 0 0" rpy="0 0 0" />
            <geometry>
                <mesh filename="package://robotino_arm_v2_udf/meshes/GR.STL" />
            </geometry>
            <material name="">
                <color rgba="0.792156862745098 0.819607843137255 0.933333333333333 1" />
            </material>
        </visual>
        <collision>
            <origin xyz="0 0 0" rpy="0 0 0" />
            <geometry>
                <mesh filename="package://robotino_arm_v2_udf/meshes/GR.STL" />
            </geometry>
        </collision>
    </link>
    <joint name="J4" type="revolute">
        <origin xyz="0.0094213 0.0036281 0.046465" rpy="3.0636 0.029147 -0.0022426" />
        <parent link="L3" />
        <child link="GR" />
        <axis xyz="0 1 0" />
        <limit lower="-1.8" upper="1.8" effort="10" velocity="0.2" />
    </joint>
    <link name="GL">
        
<inertial>
            <origin xyz="-0.00437064923464174 4.60766456037431E-05 -0.0358117241638067" rpy="0 0 0" />
            <mass value="0.0180904804143949" />
            <inertia ixx="1.04915012930938E-05" ixy="-9.96819798756622E-10" ixz="1.62170559104411E-07" iyy="6.34402248985625E-06" iyz="-1.9482740956521E-09" izz="5.68223727875759E-06" />
        </inertial>

        <visual>
            <origin xyz="0 0 0" rpy="0 0 0" />
            <geometry>
                <mesh filename="package://robotino_arm_v2_udf/meshes/GL.STL" />
            </geometry>
            <material name="">
                <color rgba="0.792156862745098 0.819607843137255 0.933333333333333 1" />
            </material>
        </visual>
        <collision>
            <origin xyz="0 0 0" rpy="0 0 0" />
            <geometry>
                <mesh filename="package://robotino_arm_v2_udf/meshes/GL.STL" />
            </geometry>
        </collision>
    </link>
    <joint name="J5" type="revolute">
        <origin xyz="0.03407 0.0036281 0.046454" rpy="-3.0636 0.040018 -3.1384" />
        <parent link="L3" />
        <child link="GL" />
        <axis xyz="0 1 0" />
        <limit lower="-1.8" upper="1.8" effort="10" velocity="0.2" />
        <mimic joint="J4" multiplier="1" offset="0" />
    </joint>
    
<transmission name="trans_J1">
        <type>transmission_interface/SimpleTransmission</type>
        <joint name="J1">
            <hardwareInterface>hardware_interface/PositionJointInterface</hardwareInterface>
        </joint>
        <actuator name="J1_motor">
            <hardwareInterface>hardware_interface/PositionJointInterface</hardwareInterface>
            <mechanicalReduction>1</mechanicalReduction>
        </actuator>
    </transmission>
    <transmission name="trans_J2">
        <type>transmission_interface/SimpleTransmission</type>
        <joint name="J2">
            <hardwareInterface>hardware_interface/PositionJointInterface</hardwareInterface>
        </joint>
        <actuator name="J2_motor">
            <hardwareInterface>hardware_interface/PositionJointInterface</hardwareInterface>
            <mechanicalReduction>1</mechanicalReduction>
        </actuator>
    </transmission>
    <transmission name="trans_J3">
        <type>transmission_interface/SimpleTransmission</type>
        <joint name="J3">
            <hardwareInterface>hardware_interface/PositionJointInterface</hardwareInterface>
        </joint>
        <actuator name="J3_motor">
            <hardwareInterface>hardware_interface/PositionJointInterface</hardwareInterface>
            <mechanicalReduction>1</mechanicalReduction>
        </actuator>
    </transmission>
    <transmission name="trans_J4">
        <type>transmission_interface/SimpleTransmission</type>
        <joint name="J4">
            <hardwareInterface>hardware_interface/PositionJointInterface</hardwareInterface>
        </joint>
        <actuator name="J4_motor">
            <hardwareInterface>hardware_interface/PositionJointInterface</hardwareInterface>
            <mechanicalReduction>1</mechanicalReduction>
        </actuator>
    </transmission>
    <transmission name="trans_J5">
        <type>transmission_interface/SimpleTransmission</type>
        <joint name="J5">
            <hardwareInterface>hardware_interface/EffortJointInterface</hardwareInterface>
        </joint>
        <actuator name="J5_motor">
            <hardwareInterface>hardware_interface/EffortJointInterface</hardwareInterface>
            <mechanicalReduction>1</mechanicalReduction>
        </actuator>
    </transmission>
    <gazebo>
        <plugin name="gazebo_ros_control" filename="libgazebo_ros_control.so">
            <robotNamespace>/</robotNamespace>
        </plugin>
    </gazebo>
</robot>
